{"date":"2019-10-17T15:28:42.143","level":"ERROR","category":"transfer2Pog.js","host":"frank-hp","pid":"13124","data":'the error is from transfer2Pog(),the error trace is Error: ["pog_account"] is not a valid attribute definition. Please use the following format: ['attribute definition', 'alias']
    at attributes.map.attr (D:\work_space\yuezhi\eos\exchange\node_modules\sequelize\lib\dialects\abstract\query-generator.js:1419:17)
    at Array.map (<anonymous>)
    at MySQLQueryGenerator.escapeAttributes (D:\work_space\yuezhi\eos\exchange\node_modules\sequelize\lib\dialects\abstract\query-generator.js:1411:37)
    at MySQLQueryGenerator.selectQuery (D:\work_space\yuezhi\eos\exchange\node_modules\sequelize\lib\dialects\abstract\query-generator.js:1168:28)
    at QueryInterface.select (D:\work_space\yuezhi\eos\exchange\node_modules\sequelize\lib\query-interface.js:1119:27)
    at Promise.try.then.then.then (D:\work_space\yuezhi\eos\exchange\node_modules\sequelize\lib\model.js:1756:34)
    at tryCatcher (D:\work_space\yuezhi\eos\exchange\node_modules\bluebird\js\release\util.js:16:23)
    at Promise._settlePromiseFromHandler (D:\work_space\yuezhi\eos\exchange\node_modules\bluebird\js\release\promise.js:517:31)
    at Promise._settlePromise (D:\work_space\yuezhi\eos\exchange\node_modules\bluebird\js\release\promise.js:574:18)
    at Promise._settlePromise0 (D:\work_space\yuezhi\eos\exchange\node_modules\bluebird\js\release\promise.js:619:10)
    at Promise._settlePromises (D:\work_space\yuezhi\eos\exchange\node_modules\bluebird\js\release\promise.js:699:18)
    at _drainQueueStep (D:\work_space\yuezhi\eos\exchange\node_modules\bluebird\js\release\async.js:138:12)
    at _drainQueue (D:\work_space\yuezhi\eos\exchange\node_modules\bluebird\js\release\async.js:131:9)
    at Async._drainQueues (D:\work_space\yuezhi\eos\exchange\node_modules\bluebird\js\release\async.js:147:5)
    at Immediate.Async.drainQueues [as _onImmediate] (D:\work_space\yuezhi\eos\exchange\node_modules\bluebird\js\release\async.js:17:14)
    at runCallback (timers.js:705:18)
    at tryOnImmediate (timers.js:676:5)
    at processImmediate (timers.js:658:5)'}
{"date":"2019-10-17T17:28:58.076","level":"ERROR","category":"transfer2Pog.js","host":"frank-hp","pid":"12452","data":'the error is from transfer2Pog(),the error trace is TypeError: sequelize.transaction is not a function
    at transfer2Pog (D:\work_space\yuezhi\eos\exchange\src\job\transfer2Pog.js:45:37)'}
{"date":"2019-10-17T17:29:59.184","level":"ERROR","category":"transfer2Pog.js","host":"frank-hp","pid":"9304","data":'the error is from transfer2Pog(),the error trace is { Error: assertion failure with message: cannot transfer to self
    at new RpcError (D:\work_space\yuezhi\eos\exchange\node_modules\eosjs\dist\eosjs-rpcerror.js:26:28)
    at JsonRpc.<anonymous> (D:\work_space\yuezhi\eos\exchange\node_modules\eosjs\dist\eosjs-jsonrpc.js:118:35)
    at step (D:\work_space\yuezhi\eos\exchange\node_modules\eosjs\dist\eosjs-jsonrpc.js:36:23)
    at Object.next (D:\work_space\yuezhi\eos\exchange\node_modules\eosjs\dist\eosjs-jsonrpc.js:17:53)
    at fulfilled (D:\work_space\yuezhi\eos\exchange\node_modules\eosjs\dist\eosjs-jsonrpc.js:8:58)
    at process._tickCallback (internal/process/next_tick.js:68:7)
  json:
   { code: 500,
     message: 'Internal Service Error',
     error:
      { code: 3050003,
        name: 'eosio_assert_message_exception',
        what: 'eosio_assert_message assertion failure',
        details: [Array] } } }'}
